<?xml version="1.0"?>
<robot xmlns:xacro="http://www.ros.org/wiki/xacro" name="barista_bot">
    <!-- Include -->
    <xacro:include filename="$(find barista_robot_description)/xacro/rviz_materials.xacro"/>
    <xacro:include filename="$(find barista_robot_description)/xacro/standoff_rods.xacro"/>
    <xacro:include filename="$(find barista_robot_description)/xacro/cup_holder_tray.xacro"/>
    <xacro:include filename="$(find barista_robot_description)/xacro/drive_wheels.xacro"/>
    <xacro:include filename="$(find barista_robot_description)/xacro/gazebo_plugins.xacro"/>

    <!-- Properties -->
    <xacro:property name="robot_name" value="barista_bot"/>
    <xacro:property name="base_plate_mass" value="0.8"/>
    <xacro:property name="base_plate_radius" value="0.178"/>
    <xacro:property name="base_plate_length" value="0.155"/>
    <!-- Calculated inertial properties -->
    <xacro:property name="ixx" value="${(1/12.0) * base_plate_mass * (3 * pow(base_plate_radius, 2) + pow(base_plate_length, 2))}"/>
    <xacro:property name="iyy" value="${(1/12.0) * base_plate_mass * (3 * pow(base_plate_radius, 2) + pow(base_plate_length, 2))}"/>
    <xacro:property name="izz" value="${0.5 * base_plate_mass * pow(base_plate_radius, 2)}"/>

    <link name="base_link"/>
    <link name="base_plate_link">
        <visual>
            <geometry>
                <cylinder radius="${base_plate_radius}" length="${base_plate_length}"/>
            </geometry>
            <material name="Blue"/>
        </visual>
        <collision>
            <geometry>
                <cylinder radius="${base_plate_radius}" length="${base_plate_length}"/>
            </geometry>
        </collision>
        <inertial>
            <mass value="${base_plate_mass}"/>
            <origin rpy="0 0 0" xyz="0 0 0"/>
            <inertia ixx="${ixx}" iyy="${iyy}" izz="${izz}" ixy="0" iyz="0" ixz="0"/>
        </inertial>
    </link>
    <gazebo reference="base_plate_link">
        <material>Gazebo/Blue</material>
    </gazebo>
    <joint name="base_link_joint" type="fixed">
        <origin rpy="0 0 0" xyz="0 0 0"/>
        <parent link="base_link"/>
        <child link="base_plate_link"/>
    </joint>
    <!-- Standoff Rods -->
    <xacro:standoff_rods name="standoff_rods1_link" color="White"/>
    <xacro:standoff_rods name="standoff_rods2_link" color="White"/>
    <xacro:standoff_rods name="standoff_rods3_link" color="White"/>
    <xacro:standoff_rods name="standoff_rods4_link" color="White"/>
    <!-- Standoff Rods Joints-->
    <joint name="standoff_rods1_joint" type="fixed">
        <origin rpy="0 0 0" xyz="0.03 0.13 0.1875"/>
        <parent link="base_plate_link"/>
        <child link="standoff_rods1_link"/>
    </joint>
    <joint name="standoff_rods2_joint" type="fixed">
        <origin rpy="0 0 0" xyz="-0.03 0.13 0.1875"/>
        <parent link="base_plate_link"/>
        <child link="standoff_rods2_link"/>
    </joint>
    <joint name="standoff_rods3_joint" type="fixed">
        <origin rpy="0 0 0" xyz="-0.03 -0.13 0.1875"/>
        <parent link="base_plate_link"/>
        <child link="standoff_rods3_link"/>
    </joint>
    <joint name="standoff_rods4_joint" type="fixed">
        <origin rpy="0 0 0" xyz="0.03 -0.13 0.1875"/>
        <parent link="base_plate_link"/>
        <child link="standoff_rods4_link"/>
    </joint>

    <!-- Cup Holder Tray -->
    <xacro:cup_holder_tray name="cup_holder_tray_link" color="Blue"/>
    <joint name="cup_holder_tray_joint" type="fixed">
        <origin rpy="0 0 0" xyz="0 0 0.3425"/>
        <parent link="base_plate_link"/>
        <child link="cup_holder_tray_link"/>
    </joint>

    <!-- Wheel Left and Right -->
    <xacro:wheel name="left_wheel_link" color="Black"/>
    <xacro:wheel name="right_wheel_link" color="Black"/>
    <!-- Wheel Left and Right Joints-->
    <joint name="left_wheel_joint" type="continuous">
        <parent link="base_plate_link"/>
        <child link="left_wheel_link"/>
        <origin xyz="0.0 0.15 -0.053" rpy="-1.57 0 0"/>
        <axis rpy="0 0 0" xyz="0 0 1"/>
        <limit effort="10000" velocity="1000"/>
        <joint_properties damping="1.0" friction="1.0"/>
    </joint>
    <joint name="right_wheel_joint" type="continuous">
        <parent link="base_plate_link"/>
        <child link="right_wheel_link"/>
        <origin xyz="0.0 -0.15 -0.053" rpy="-1.57 0 0"/>
        <axis rpy="0 0 0" xyz="0 0 1"/>
        <limit effort="10000" velocity="1000"/>
        <joint_properties damping="1.0" friction="1.0"/>
    </joint>
    <xacro:joint_state_publisher_plugin
        robot_name="${robot_name}"
        rate="50"
        joints="${[
            'left_wheel_joint',
            'right_wheel_joint'
        ]}"/>
</robot>
